{"trial_id": "01", "hyperparameters": {"space": [{"class_name": "Choice", "config": {"name": "filters", "default": 32, "conditions": [], "values": [32, 64, 128], "ordered": true}}, {"class_name": "Choice", "config": {"name": "kernel_size", "default": 2, "conditions": [], "values": [2, 3, 5], "ordered": true}}, {"class_name": "Choice", "config": {"name": "pool_size", "default": 2, "conditions": [], "values": [2, 3], "ordered": true}}, {"class_name": "Float", "config": {"name": "dropout_conv", "default": 0.1, "conditions": [], "min_value": 0.1, "max_value": 0.5, "step": 0.1, "sampling": "linear"}}, {"class_name": "Choice", "config": {"name": "units1", "default": 64, "conditions": [], "values": [64, 128, 256], "ordered": true}}, {"class_name": "Choice", "config": {"name": "units2", "default": 32, "conditions": [], "values": [32, 64, 128], "ordered": true}}, {"class_name": "Float", "config": {"name": "dropout1", "default": 0.1, "conditions": [], "min_value": 0.1, "max_value": 0.5, "step": 0.1, "sampling": "linear"}}, {"class_name": "Float", "config": {"name": "dropout2", "default": 0.1, "conditions": [], "min_value": 0.1, "max_value": 0.5, "step": 0.1, "sampling": "linear"}}, {"class_name": "Choice", "config": {"name": "lr", "default": 0.01, "conditions": [], "values": [0.01, 0.001, 0.0001], "ordered": true}}], "values": {"filters": 32, "kernel_size": 2, "pool_size": 2, "dropout_conv": 0.1, "units1": 64, "units2": 128, "dropout1": 0.30000000000000004, "dropout2": 0.2, "lr": 0.0001}}, "metrics": {"metrics": {}}, "score": null, "best_step": 0, "status": "FAILED", "message": "Traceback (most recent call last):\n  File \"c:\\Users\\giakh\\miniconda3\\envs\\ai_train\\Lib\\site-packages\\keras_tuner\\src\\engine\\base_tuner.py\", line 274, in _try_run_and_update_trial\n    self._run_and_update_trial(trial, *fit_args, **fit_kwargs)\n  File \"c:\\Users\\giakh\\miniconda3\\envs\\ai_train\\Lib\\site-packages\\keras_tuner\\src\\engine\\base_tuner.py\", line 239, in _run_and_update_trial\n    results = self.run_trial(trial, *fit_args, **fit_kwargs)\n              ^^^^^^^^^^^^^^^^^^^^^^^^^^^^^^^^^^^^^^^^^^^^^^\n  File \"c:\\Users\\giakh\\miniconda3\\envs\\ai_train\\Lib\\site-packages\\keras_tuner\\src\\engine\\tuner.py\", line 314, in run_trial\n    obj_value = self._build_and_fit_model(trial, *args, **copied_kwargs)\n                ^^^^^^^^^^^^^^^^^^^^^^^^^^^^^^^^^^^^^^^^^^^^^^^^^^^^^^^^\n  File \"c:\\Users\\giakh\\miniconda3\\envs\\ai_train\\Lib\\site-packages\\keras_tuner\\src\\engine\\tuner.py\", line 233, in _build_and_fit_model\n    results = self.hypermodel.fit(hp, model, *args, **kwargs)\n              ^^^^^^^^^^^^^^^^^^^^^^^^^^^^^^^^^^^^^^^^^^^^^^^\n  File \"c:\\Users\\giakh\\miniconda3\\envs\\ai_train\\Lib\\site-packages\\keras_tuner\\src\\engine\\hypermodel.py\", line 149, in fit\n    return model.fit(*args, **kwargs)\n           ^^^^^^^^^^^^^^^^^^^^^^^^^^\n  File \"c:\\Users\\giakh\\miniconda3\\envs\\ai_train\\Lib\\site-packages\\keras\\src\\utils\\traceback_utils.py\", line 122, in error_handler\n    raise e.with_traceback(filtered_tb) from None\n  File \"c:\\Users\\giakh\\miniconda3\\envs\\ai_train\\Lib\\site-packages\\keras\\src\\utils\\traceback_utils.py\", line 124, in error_handler\n    del filtered_tb\n        ^^^^^^^^^^^\nValueError: Exception encountered when calling Conv1D.call().\n\n\u001b[1mNegative dimension size caused by subtracting 2 from 1 for '{{node sequential_1/conv1d_1/convolution}} = Conv2D[T=DT_FLOAT, data_format=\"NHWC\", dilations=[1, 1, 1, 1], explicit_paddings=[], padding=\"VALID\", strides=[1, 1, 1, 1], use_cudnn_on_gpu=true](sequential_1/conv1d_1/convolution/ExpandDims, sequential_1/conv1d_1/convolution/ExpandDims_1)' with input shapes: [?,1,1,14], [1,2,14,32].\u001b[0m\n\nArguments received by Conv1D.call():\n  \u2022 inputs=tf.Tensor(shape=(None, 1, 14), dtype=float32)\n"}